Traceback (most recent call last):
  File "/home/tbent/.miniconda3/envs/bie_book/lib/python3.9/site-packages/jupyter_cache/executors/utils.py", line 51, in single_nb_execution
    executenb(
  File "/home/tbent/.miniconda3/envs/bie_book/lib/python3.9/site-packages/nbclient/client.py", line 1112, in execute
    return NotebookClient(nb=nb, resources=resources, km=km, **kwargs).execute()
  File "/home/tbent/.miniconda3/envs/bie_book/lib/python3.9/site-packages/nbclient/util.py", line 74, in wrapped
    return just_run(coro(*args, **kwargs))
  File "/home/tbent/.miniconda3/envs/bie_book/lib/python3.9/site-packages/nbclient/util.py", line 53, in just_run
    return loop.run_until_complete(coro)
  File "/home/tbent/.miniconda3/envs/bie_book/lib/python3.9/asyncio/base_events.py", line 642, in run_until_complete
    return future.result()
  File "/home/tbent/.miniconda3/envs/bie_book/lib/python3.9/site-packages/nbclient/client.py", line 553, in async_execute
    await self.async_execute_cell(
  File "/home/tbent/.miniconda3/envs/bie_book/lib/python3.9/site-packages/nbclient/client.py", line 857, in async_execute_cell
    self._check_raise_for_error(cell, exec_reply)
  File "/home/tbent/.miniconda3/envs/bie_book/lib/python3.9/site-packages/nbclient/client.py", line 760, in _check_raise_for_error
    raise CellExecutionError.from_cell_and_msg(cell, exec_reply_content)
nbclient.exceptions.CellExecutionError: An error occurred while executing the following cell:
------------------
import numpy as np
import matplotlib.pyplot as plt
import common
import sympy as sp

%config InlineBackend.figure_format='retina'

n_q = 100
circle_rule = list(common.trapezoidal_rule(n_q))

t = sp.symbols("t")
theta = sp.pi * (t + 1)
circle_rule[1] *= np.pi

sym_circle = common.symbolic_suvrface(t, sp.cos(theta), sp.sin(theta))
circle = common.symbolic_eval(t, circle_rule[0], sym_circle)
------------------

[0;31m---------------------------------------------------------------------------[0m
[0;31mAttributeError[0m                            Traceback (most recent call last)
[0;32m<ipython-input-1-c3fd217b0b0b>[0m in [0;36m<module>[0;34m[0m
[1;32m     13[0m [0mcircle_rule[0m[0;34m[[0m[0;36m1[0m[0;34m][0m [0;34m*=[0m [0mnp[0m[0;34m.[0m[0mpi[0m[0;34m[0m[0;34m[0m[0m
[1;32m     14[0m [0;34m[0m[0m
[0;32m---> 15[0;31m [0msym_circle[0m [0;34m=[0m [0mcommon[0m[0;34m.[0m[0msymbolic_suvrface[0m[0;34m([0m[0mt[0m[0;34m,[0m [0msp[0m[0;34m.[0m[0mcos[0m[0;34m([0m[0mtheta[0m[0;34m)[0m[0;34m,[0m [0msp[0m[0;34m.[0m[0msin[0m[0;34m([0m[0mtheta[0m[0;34m)[0m[0;34m)[0m[0;34m[0m[0;34m[0m[0m
[0m[1;32m     16[0m [0mcircle[0m [0;34m=[0m [0mcommon[0m[0;34m.[0m[0msymbolic_eval[0m[0;34m([0m[0mt[0m[0;34m,[0m [0mcircle_rule[0m[0;34m[[0m[0;36m0[0m[0;34m][0m[0;34m,[0m [0msym_circle[0m[0;34m)[0m[0;34m[0m[0;34m[0m[0m

[0;31mAttributeError[0m: module 'common' has no attribute 'symbolic_suvrface'
AttributeError: module 'common' has no attribute 'symbolic_suvrface'

