Traceback (most recent call last):
  File "/home/tbent/.miniconda3/envs/bie_book/lib/python3.9/site-packages/jupyter_cache/executors/utils.py", line 51, in single_nb_execution
    executenb(
  File "/home/tbent/.miniconda3/envs/bie_book/lib/python3.9/site-packages/nbclient/client.py", line 1112, in execute
    return NotebookClient(nb=nb, resources=resources, km=km, **kwargs).execute()
  File "/home/tbent/.miniconda3/envs/bie_book/lib/python3.9/site-packages/nbclient/util.py", line 74, in wrapped
    return just_run(coro(*args, **kwargs))
  File "/home/tbent/.miniconda3/envs/bie_book/lib/python3.9/site-packages/nbclient/util.py", line 53, in just_run
    return loop.run_until_complete(coro)
  File "/home/tbent/.miniconda3/envs/bie_book/lib/python3.9/asyncio/base_events.py", line 642, in run_until_complete
    return future.result()
  File "/home/tbent/.miniconda3/envs/bie_book/lib/python3.9/site-packages/nbclient/client.py", line 553, in async_execute
    await self.async_execute_cell(
  File "/home/tbent/.miniconda3/envs/bie_book/lib/python3.9/site-packages/nbclient/client.py", line 857, in async_execute_cell
    self._check_raise_for_error(cell, exec_reply)
  File "/home/tbent/.miniconda3/envs/bie_book/lib/python3.9/site-packages/nbclient/client.py", line 760, in _check_raise_for_error
    raise CellExecutionError.from_cell_and_msg(cell, exec_reply_content)
nbclient.exceptions.CellExecutionError: An error occurred while executing the following cell:
------------------
qbx_p = 5
qbx_center_x, qbx_center_y, qbx_r = qbx_choose_centers(flat, qr_flat)
qbx_expand_flat = qbx_expand_matrix(double_layer_matrix, flat, qr_flat, qbx_center_x, qbx_center_y, qbx_r, qbx_p=qbx_p)
qbx_eval_flat = qbx_eval_matrix(flat[0][None,:], flat[1][None,:], qbx_center_x, qbx_center_y, qbx_p=qbx_p)[0]
A = np.real(np.sum(qbx_eval_flat[:,:,None] * qbx_expand_flat, axis=1))
------------------

[0;31m---------------------------------------------------------------------------[0m
[0;31mMemoryError[0m                               Traceback (most recent call last)
[0;32m<ipython-input-9-5d480f6339f1>[0m in [0;36m<module>[0;34m[0m
[1;32m      3[0m [0mqbx_expand_flat[0m [0;34m=[0m [0mqbx_expand_matrix[0m[0;34m([0m[0mdouble_layer_matrix[0m[0;34m,[0m [0mflat[0m[0;34m,[0m [0mqr_flat[0m[0;34m,[0m [0mqbx_center_x[0m[0;34m,[0m [0mqbx_center_y[0m[0;34m,[0m [0mqbx_r[0m[0;34m,[0m [0mqbx_p[0m[0;34m=[0m[0mqbx_p[0m[0;34m)[0m[0;34m[0m[0;34m[0m[0m
[1;32m      4[0m [0mqbx_eval_flat[0m [0;34m=[0m [0mqbx_eval_matrix[0m[0;34m([0m[0mflat[0m[0;34m[[0m[0;36m0[0m[0;34m][0m[0;34m[[0m[0;32mNone[0m[0;34m,[0m[0;34m:[0m[0;34m][0m[0;34m,[0m [0mflat[0m[0;34m[[0m[0;36m1[0m[0;34m][0m[0;34m[[0m[0;32mNone[0m[0;34m,[0m[0;34m:[0m[0;34m][0m[0;34m,[0m [0mqbx_center_x[0m[0;34m,[0m [0mqbx_center_y[0m[0;34m,[0m [0mqbx_p[0m[0;34m=[0m[0mqbx_p[0m[0;34m)[0m[0;34m[[0m[0;36m0[0m[0;34m][0m[0;34m[0m[0;34m[0m[0m
[0;32m----> 5[0;31m [0mA[0m [0;34m=[0m [0mnp[0m[0;34m.[0m[0mreal[0m[0;34m([0m[0mnp[0m[0;34m.[0m[0msum[0m[0;34m([0m[0mqbx_eval_flat[0m[0;34m[[0m[0;34m:[0m[0;34m,[0m[0;34m:[0m[0;34m,[0m[0;32mNone[0m[0;34m][0m [0;34m*[0m [0mqbx_expand_flat[0m[0;34m,[0m [0maxis[0m[0;34m=[0m[0;36m1[0m[0;34m)[0m[0;34m)[0m[0;34m[0m[0;34m[0m[0m
[0m
[0;31mMemoryError[0m: Unable to allocate 1.14 TiB for an array with shape (2500, 2500, 5, 2500) and data type complex128
MemoryError: Unable to allocate 1.14 TiB for an array with shape (2500, 2500, 5, 2500) and data type complex128

